ERROR:TeleBot:ConnectionError occurred, args=(MaxRetryError("HTTPSConnectionPool(host='api.telegram.org', port=443): Max retries exceeded with url: /bot622726947:AAHOVDDfxJDbxyMNFBYx72OZfHPPG8AvnUY/getUpdates?offset=1&timeout=20 (Caused by NewConnectionError('<urllib3.connection.HTTPSConnection object at 0x0467EB08>: Failed to establish a new connection: [WinError 10061] Подключение не установлено, т.к. конечный компьютер отверг запрос на подключение'))"),)
Traceback (most recent call last):
  File "C:\Users\radus\PycharmProjects\untitled\venv\lib\site-packages\urllib3\connection.py", line 159, in _new_conn
    conn = connection.create_connection(
  File "C:\Users\radus\PycharmProjects\untitled\venv\lib\site-packages\urllib3\util\connection.py", line 84, in create_connection
    raise err
  File "C:\Users\radus\PycharmProjects\untitled\venv\lib\site-packages\urllib3\util\connection.py", line 74, in create_connection
    sock.connect(sa)
ConnectionRefusedError: [WinError 10061] Подключение не установлено, т.к. конечный компьютер отверг запрос на подключение

During handling of the above exception, another exception occurred:

Traceback (most recent call last):
  File "C:\Users\radus\PycharmProjects\untitled\venv\lib\site-packages\urllib3\connectionpool.py", line 670, in urlopen
    httplib_response = self._make_request(
  File "C:\Users\radus\PycharmProjects\untitled\venv\lib\site-packages\urllib3\connectionpool.py", line 381, in _make_request
    self._validate_conn(conn)
  File "C:\Users\radus\PycharmProjects\untitled\venv\lib\site-packages\urllib3\connectionpool.py", line 976, in _validate_conn
    conn.connect()
  File "C:\Users\radus\PycharmProjects\untitled\venv\lib\site-packages\urllib3\connection.py", line 308, in connect
    conn = self._new_conn()
  File "C:\Users\radus\PycharmProjects\untitled\venv\lib\site-packages\urllib3\connection.py", line 171, in _new_conn
    raise NewConnectionError(
urllib3.exceptions.NewConnectionError: <urllib3.connection.HTTPSConnection object at 0x0467EB08>: Failed to establish a new connection: [WinError 10061] Подключение не установлено, т.к. конечный компьютер отверг запрос на подключение

During handling of the above exception, another exception occurred:

Traceback (most recent call last):
  File "C:\Users\radus\PycharmProjects\untitled\venv\lib\site-packages\requests\adapters.py", line 439, in send
    resp = conn.urlopen(
  File "C:\Users\radus\PycharmProjects\untitled\venv\lib\site-packages\urllib3\connectionpool.py", line 724, in urlopen
    retries = retries.increment(
  File "C:\Users\radus\PycharmProjects\untitled\venv\lib\site-packages\urllib3\util\retry.py", line 439, in increment
    raise MaxRetryError(_pool, url, error or ResponseError(cause))
urllib3.exceptions.MaxRetryError: HTTPSConnectionPool(host='api.telegram.org', port=443): Max retries exceeded with url: /bot622726947:AAHOVDDfxJDbxyMNFBYx72OZfHPPG8AvnUY/getUpdates?offset=1&timeout=20 (Caused by NewConnectionError('<urllib3.connection.HTTPSConnection object at 0x0467EB08>: Failed to establish a new connection: [WinError 10061] Подключение не установлено, т.к. конечный компьютер отверг запрос на подключение'))

During handling of the above exception, another exception occurred:

Traceback (most recent call last):
  File "C:\Users\radus\PycharmProjects\untitled\venv\lib\site-packages\telebot\util.py", line 60, in run
    task(*args, **kwargs)
  File "C:\Users\radus\PycharmProjects\untitled\venv\lib\site-packages\telebot\__init__.py", line 279, in __retrieve_updates
    updates = self.get_updates(offset=(self.last_update_id + 1), timeout=timeout)
  File "C:\Users\radus\PycharmProjects\untitled\venv\lib\site-packages\telebot\__init__.py", line 249, in get_updates
    json_updates = apihelper.get_updates(self.token, offset, limit, timeout, allowed_updates)
  File "C:\Users\radus\PycharmProjects\untitled\venv\lib\site-packages\telebot\apihelper.py", line 194, in get_updates
    return _make_request(token, method_url, params=payload)
  File "C:\Users\radus\PycharmProjects\untitled\venv\lib\site-packages\telebot\apihelper.py", line 57, in _make_request
    result = _get_req_session().request(method, request_url, params=params, files=files,
  File "C:\Users\radus\PycharmProjects\untitled\venv\lib\site-packages\requests\sessions.py", line 530, in request
    resp = self.send(prep, **send_kwargs)
  File "C:\Users\radus\PycharmProjects\untitled\venv\lib\site-packages\requests\sessions.py", line 643, in send
    r = adapter.send(request, **kwargs)
  File "C:\Users\radus\PycharmProjects\untitled\venv\lib\site-packages\requests\adapters.py", line 516, in send
    raise ConnectionError(e, request=request)
requests.exceptions.ConnectionError: HTTPSConnectionPool(host='api.telegram.org', port=443): Max retries exceeded with url: /bot622726947:AAHOVDDfxJDbxyMNFBYx72OZfHPPG8AvnUY/getUpdates?offset=1&timeout=20 (Caused by NewConnectionError('<urllib3.connection.HTTPSConnection object at 0x0467EB08>: Failed to establish a new connection: [WinError 10061] Подключение не установлено, т.к. конечный компьютер отверг запрос на подключение'))

ERROR:root:HTTPSConnectionPool(host='api.telegram.org', port=443): Max retries exceeded with url: /bot622726947:AAHOVDDfxJDbxyMNFBYx72OZfHPPG8AvnUY/getUpdates?offset=1&timeout=20 (Caused by NewConnectionError('<urllib3.connection.HTTPSConnection object at 0x0467EB08>: Failed to establish a new connection: [WinError 10061] Подключение не установлено, т.к. конечный компьютер отверг запрос на подключение'))
ERROR:TeleBot:ConnectionError occurred, args=(MaxRetryError("HTTPSConnectionPool(host='api.telegram.org', port=443): Max retries exceeded with url: /bot622726947:AAHOVDDfxJDbxyMNFBYx72OZfHPPG8AvnUY/getUpdates?offset=1&timeout=20 (Caused by NewConnectionError('<urllib3.connection.HTTPSConnection object at 0x04FC85B0>: Failed to establish a new connection: [WinError 10061] Подключение не установлено, т.к. конечный компьютер отверг запрос на подключение'))"),)
Traceback (most recent call last):
  File "C:\Users\radus\PycharmProjects\untitled\venv\lib\site-packages\urllib3\connection.py", line 159, in _new_conn
    conn = connection.create_connection(
  File "C:\Users\radus\PycharmProjects\untitled\venv\lib\site-packages\urllib3\util\connection.py", line 84, in create_connection
    raise err
  File "C:\Users\radus\PycharmProjects\untitled\venv\lib\site-packages\urllib3\util\connection.py", line 74, in create_connection
    sock.connect(sa)
ConnectionRefusedError: [WinError 10061] Подключение не установлено, т.к. конечный компьютер отверг запрос на подключение

During handling of the above exception, another exception occurred:

Traceback (most recent call last):
  File "C:\Users\radus\PycharmProjects\untitled\venv\lib\site-packages\urllib3\connectionpool.py", line 670, in urlopen
    httplib_response = self._make_request(
  File "C:\Users\radus\PycharmProjects\untitled\venv\lib\site-packages\urllib3\connectionpool.py", line 381, in _make_request
    self._validate_conn(conn)
  File "C:\Users\radus\PycharmProjects\untitled\venv\lib\site-packages\urllib3\connectionpool.py", line 976, in _validate_conn
    conn.connect()
  File "C:\Users\radus\PycharmProjects\untitled\venv\lib\site-packages\urllib3\connection.py", line 308, in connect
    conn = self._new_conn()
  File "C:\Users\radus\PycharmProjects\untitled\venv\lib\site-packages\urllib3\connection.py", line 171, in _new_conn
    raise NewConnectionError(
urllib3.exceptions.NewConnectionError: <urllib3.connection.HTTPSConnection object at 0x04FC85B0>: Failed to establish a new connection: [WinError 10061] Подключение не установлено, т.к. конечный компьютер отверг запрос на подключение

During handling of the above exception, another exception occurred:

Traceback (most recent call last):
  File "C:\Users\radus\PycharmProjects\untitled\venv\lib\site-packages\requests\adapters.py", line 439, in send
    resp = conn.urlopen(
  File "C:\Users\radus\PycharmProjects\untitled\venv\lib\site-packages\urllib3\connectionpool.py", line 724, in urlopen
    retries = retries.increment(
  File "C:\Users\radus\PycharmProjects\untitled\venv\lib\site-packages\urllib3\util\retry.py", line 439, in increment
    raise MaxRetryError(_pool, url, error or ResponseError(cause))
urllib3.exceptions.MaxRetryError: HTTPSConnectionPool(host='api.telegram.org', port=443): Max retries exceeded with url: /bot622726947:AAHOVDDfxJDbxyMNFBYx72OZfHPPG8AvnUY/getUpdates?offset=1&timeout=20 (Caused by NewConnectionError('<urllib3.connection.HTTPSConnection object at 0x04FC85B0>: Failed to establish a new connection: [WinError 10061] Подключение не установлено, т.к. конечный компьютер отверг запрос на подключение'))

During handling of the above exception, another exception occurred:

Traceback (most recent call last):
  File "C:\Users\radus\PycharmProjects\untitled\venv\lib\site-packages\telebot\util.py", line 60, in run
    task(*args, **kwargs)
  File "C:\Users\radus\PycharmProjects\untitled\venv\lib\site-packages\telebot\__init__.py", line 279, in __retrieve_updates
    updates = self.get_updates(offset=(self.last_update_id + 1), timeout=timeout)
  File "C:\Users\radus\PycharmProjects\untitled\venv\lib\site-packages\telebot\__init__.py", line 249, in get_updates
    json_updates = apihelper.get_updates(self.token, offset, limit, timeout, allowed_updates)
  File "C:\Users\radus\PycharmProjects\untitled\venv\lib\site-packages\telebot\apihelper.py", line 194, in get_updates
    return _make_request(token, method_url, params=payload)
  File "C:\Users\radus\PycharmProjects\untitled\venv\lib\site-packages\telebot\apihelper.py", line 57, in _make_request
    result = _get_req_session().request(method, request_url, params=params, files=files,
  File "C:\Users\radus\PycharmProjects\untitled\venv\lib\site-packages\requests\sessions.py", line 530, in request
    resp = self.send(prep, **send_kwargs)
  File "C:\Users\radus\PycharmProjects\untitled\venv\lib\site-packages\requests\sessions.py", line 643, in send
    r = adapter.send(request, **kwargs)
  File "C:\Users\radus\PycharmProjects\untitled\venv\lib\site-packages\requests\adapters.py", line 516, in send
    raise ConnectionError(e, request=request)
requests.exceptions.ConnectionError: HTTPSConnectionPool(host='api.telegram.org', port=443): Max retries exceeded with url: /bot622726947:AAHOVDDfxJDbxyMNFBYx72OZfHPPG8AvnUY/getUpdates?offset=1&timeout=20 (Caused by NewConnectionError('<urllib3.connection.HTTPSConnection object at 0x04FC85B0>: Failed to establish a new connection: [WinError 10061] Подключение не установлено, т.к. конечный компьютер отверг запрос на подключение'))

ERROR:root:HTTPSConnectionPool(host='api.telegram.org', port=443): Max retries exceeded with url: /bot622726947:AAHOVDDfxJDbxyMNFBYx72OZfHPPG8AvnUY/getUpdates?offset=1&timeout=20 (Caused by NewConnectionError('<urllib3.connection.HTTPSConnection object at 0x04FC85B0>: Failed to establish a new connection: [WinError 10061] Подключение не установлено, т.к. конечный компьютер отверг запрос на подключение'))
ERROR:TeleBot:ConnectionError occurred, args=(MaxRetryError("HTTPSConnectionPool(host='api.telegram.org', port=443): Max retries exceeded with url: /bot622726947:AAHOVDDfxJDbxyMNFBYx72OZfHPPG8AvnUY/getUpdates?offset=1&timeout=20 (Caused by NewConnectionError('<urllib3.connection.HTTPSConnection object at 0x04FC8EF8>: Failed to establish a new connection: [WinError 10061] Подключение не установлено, т.к. конечный компьютер отверг запрос на подключение'))"),)
Traceback (most recent call last):
  File "C:\Users\radus\PycharmProjects\untitled\venv\lib\site-packages\urllib3\connection.py", line 159, in _new_conn
    conn = connection.create_connection(
  File "C:\Users\radus\PycharmProjects\untitled\venv\lib\site-packages\urllib3\util\connection.py", line 84, in create_connection
    raise err
  File "C:\Users\radus\PycharmProjects\untitled\venv\lib\site-packages\urllib3\util\connection.py", line 74, in create_connection
    sock.connect(sa)
ConnectionRefusedError: [WinError 10061] Подключение не установлено, т.к. конечный компьютер отверг запрос на подключение

During handling of the above exception, another exception occurred:

Traceback (most recent call last):
  File "C:\Users\radus\PycharmProjects\untitled\venv\lib\site-packages\urllib3\connectionpool.py", line 670, in urlopen
    httplib_response = self._make_request(
  File "C:\Users\radus\PycharmProjects\untitled\venv\lib\site-packages\urllib3\connectionpool.py", line 381, in _make_request
    self._validate_conn(conn)
  File "C:\Users\radus\PycharmProjects\untitled\venv\lib\site-packages\urllib3\connectionpool.py", line 976, in _validate_conn
    conn.connect()
  File "C:\Users\radus\PycharmProjects\untitled\venv\lib\site-packages\urllib3\connection.py", line 308, in connect
    conn = self._new_conn()
  File "C:\Users\radus\PycharmProjects\untitled\venv\lib\site-packages\urllib3\connection.py", line 171, in _new_conn
    raise NewConnectionError(
urllib3.exceptions.NewConnectionError: <urllib3.connection.HTTPSConnection object at 0x04FC8EF8>: Failed to establish a new connection: [WinError 10061] Подключение не установлено, т.к. конечный компьютер отверг запрос на подключение

During handling of the above exception, another exception occurred:

Traceback (most recent call last):
  File "C:\Users\radus\PycharmProjects\untitled\venv\lib\site-packages\requests\adapters.py", line 439, in send
    resp = conn.urlopen(
  File "C:\Users\radus\PycharmProjects\untitled\venv\lib\site-packages\urllib3\connectionpool.py", line 724, in urlopen
    retries = retries.increment(
  File "C:\Users\radus\PycharmProjects\untitled\venv\lib\site-packages\urllib3\util\retry.py", line 439, in increment
    raise MaxRetryError(_pool, url, error or ResponseError(cause))
urllib3.exceptions.MaxRetryError: HTTPSConnectionPool(host='api.telegram.org', port=443): Max retries exceeded with url: /bot622726947:AAHOVDDfxJDbxyMNFBYx72OZfHPPG8AvnUY/getUpdates?offset=1&timeout=20 (Caused by NewConnectionError('<urllib3.connection.HTTPSConnection object at 0x04FC8EF8>: Failed to establish a new connection: [WinError 10061] Подключение не установлено, т.к. конечный компьютер отверг запрос на подключение'))

During handling of the above exception, another exception occurred:

Traceback (most recent call last):
  File "C:\Users\radus\PycharmProjects\untitled\venv\lib\site-packages\telebot\util.py", line 60, in run
    task(*args, **kwargs)
  File "C:\Users\radus\PycharmProjects\untitled\venv\lib\site-packages\telebot\__init__.py", line 279, in __retrieve_updates
    updates = self.get_updates(offset=(self.last_update_id + 1), timeout=timeout)
  File "C:\Users\radus\PycharmProjects\untitled\venv\lib\site-packages\telebot\__init__.py", line 249, in get_updates
    json_updates = apihelper.get_updates(self.token, offset, limit, timeout, allowed_updates)
  File "C:\Users\radus\PycharmProjects\untitled\venv\lib\site-packages\telebot\apihelper.py", line 194, in get_updates
    return _make_request(token, method_url, params=payload)
  File "C:\Users\radus\PycharmProjects\untitled\venv\lib\site-packages\telebot\apihelper.py", line 57, in _make_request
    result = _get_req_session().request(method, request_url, params=params, files=files,
  File "C:\Users\radus\PycharmProjects\untitled\venv\lib\site-packages\requests\sessions.py", line 530, in request
    resp = self.send(prep, **send_kwargs)
  File "C:\Users\radus\PycharmProjects\untitled\venv\lib\site-packages\requests\sessions.py", line 643, in send
    r = adapter.send(request, **kwargs)
  File "C:\Users\radus\PycharmProjects\untitled\venv\lib\site-packages\requests\adapters.py", line 516, in send
    raise ConnectionError(e, request=request)
requests.exceptions.ConnectionError: HTTPSConnectionPool(host='api.telegram.org', port=443): Max retries exceeded with url: /bot622726947:AAHOVDDfxJDbxyMNFBYx72OZfHPPG8AvnUY/getUpdates?offset=1&timeout=20 (Caused by NewConnectionError('<urllib3.connection.HTTPSConnection object at 0x04FC8EF8>: Failed to establish a new connection: [WinError 10061] Подключение не установлено, т.к. конечный компьютер отверг запрос на подключение'))

ERROR:root:HTTPSConnectionPool(host='api.telegram.org', port=443): Max retries exceeded with url: /bot622726947:AAHOVDDfxJDbxyMNFBYx72OZfHPPG8AvnUY/getUpdates?offset=1&timeout=20 (Caused by NewConnectionError('<urllib3.connection.HTTPSConnection object at 0x04FC8EF8>: Failed to establish a new connection: [WinError 10061] Подключение не установлено, т.к. конечный компьютер отверг запрос на подключение'))
